<mujoco model='digit-v3'>
  <compiler angle='degree' eulerseq='xyz' meshdir='stl'/>
  <option iterations='50' solver='Newton' timestep='0.0005' gravity='0 0 -9.806'/>
  <size nconmax='100' />
  <asset>
    <material name='collision' rgba='0.1 0.5 0.9 0.4'/>
    <material name='plane' reflectance='0.000000' texrepeat='1 1' texture='plane' texuniform='true'/>
    <material name='robot' rgba='0.9 0.5 0.1 1'/>
    <texture builtin='checker' height='512' name='plane' rgb1='0.2 0.2 0.2' rgb2='0.3 0.3 0.3' type='2d' width='512'/>
    <texture builtin='gradient' height='128' rgb1='0.4 0.6 0.8' rgb2='0 0 0' type='skybox' width='128'/>
    <mesh name='base-0' file='torso.stl'/>
    <mesh name='base-1' file='hip-roll-housing.stl'/>
    <mesh name='base-2' scale='1 -1 1' file='hip-roll-housing.stl'/>
    <mesh name='base-3' file='shoulder-roll-housing.stl'/>
    <mesh name='base-4' scale='1 -1 1' file='shoulder-roll-housing.stl'/>
    <mesh name='left-hip-roll-0' file='hip-yaw-housing.stl'/>
    <mesh name='left-hip-yaw-0' file='hip-pitch-housing.stl'/>
    <mesh name='left-hip-pitch-0' file='hip-pitch.stl'/>
    <mesh name='left-achilles-rod-0' file='achilles-rod.stl'/>
    <mesh name='left-knee-0' file='knee.stl'/>
    <mesh name='left-shin-0' file='shin.stl'/>
    <mesh name='left-tarsus-0' file='tarsus.stl'/>
    <mesh name='left-heel-spring-0' file='heel-spring.stl'/>
    <mesh name='left-toe-A-0' file='toe-output.stl'/>
    <mesh name='left-toe-A-rod-0' file='toe-A-rod.stl'/>
    <mesh name='left-toe-B-0' file='toe-output.stl'/>
    <mesh name='left-toe-B-rod-0' file='toe-B-rod.stl'/>
    <mesh name='left-toe-pitch-0' file='toe-pitch.stl'/>
    <mesh name='left-toe-roll-0' file='toe-roll.stl'/>
    <mesh name='left-shoulder-roll-0' file='arm-L1.stl'/>
    <mesh name='left-shoulder-pitch-0' file='arm-L2.stl'/>
    <mesh name='left-shoulder-yaw-0' file='arm-L3.stl'/>
    <mesh name='left-elbow-0' file='arm-L4.stl'/>
    <mesh name='right-hip-roll-0' scale='1 -1 1' file='hip-yaw-housing.stl'/>
    <mesh name='right-hip-yaw-0' scale='1 -1 1' file='hip-pitch-housing.stl'/>
    <mesh name='right-hip-pitch-0' scale='1 -1 1' file='hip-pitch.stl'/>
    <mesh name='right-achilles-rod-0' scale='1 -1 1' file='achilles-rod.stl'/>
    <mesh name='right-knee-0' scale='1 -1 1' file='knee.stl'/>
    <mesh name='right-shin-0' scale='1 -1 1' file='shin.stl'/>
    <mesh name='right-tarsus-0' scale='1 -1 1' file='tarsus.stl'/>
    <mesh name='right-heel-spring-0' scale='1 -1 1' file='heel-spring.stl'/>
    <mesh name='right-toe-A-0' scale='1 -1 1' file='toe-output.stl'/>
    <mesh name='right-toe-A-rod-0' scale='1 -1 1' file='toe-A-rod.stl'/>
    <mesh name='right-toe-B-0' scale='1 -1 1' file='toe-output.stl'/>
    <mesh name='right-toe-B-rod-0' scale='1 -1 1' file='toe-B-rod.stl'/>
    <mesh name='right-toe-pitch-0' scale='1 -1 1' file='toe-pitch.stl'/>
    <mesh name='right-toe-roll-0' scale='1 -1 1' file='toe-roll.stl'/>
    <mesh name='right-shoulder-roll-0' scale='1 -1 1' file='arm-L1.stl'/>
    <mesh name='right-shoulder-pitch-0' scale='1 -1 1' file='arm-L2.stl'/>
    <mesh name='right-shoulder-yaw-0' scale='1 -1 1' file='arm-L3.stl'/>
    <mesh name='right-elbow-0' scale='1 -1 1' file='arm-L4.stl'/>
  </asset>
  <default>
    <default class='collision'>
      <geom conaffinity='1' condim='3' contype='1'/>
    </default>
    <equality solimp='0.9 0.95 0.001 0.1 2' solref='0.001 1.1' />
    <geom conaffinity='0' condim='1' contype='0' solref='0.005 1' />
    <joint solreflimit='0.001 1' />
    <motor ctrllimited="true"/>
  </default>
  <worldbody>
    <light cutoff='100' diffuse='1 1 1' dir='-0 0 -1.3' directional='true' exponent='1' pos='0 0 1.3' specular='.1 .1 .1' />  
    <geom name='ground' type='plane' material='plane' size='0 0 1' conaffinity='15' condim='3' friction='0.7 0.01 0.005' pos='0 0 0' priority='100' />
    <body name='base' pos='0 0 1' euler='-0 0 -0'>
      <inertial pos='0.001637 0.0002 0.259307' mass='15.028392' fullinertia='0.375905 0.344193 0.098732 -8.8e-05 0.0085 6.6e-05' />
      <joint type='free' limited='false'/>
      <geom type='mesh' mesh='base-0' pos='0 0 0' euler='-0 0 -0' material='robot'/>
      <geom type='mesh' mesh='base-1' pos='-0.001 0.091 0' euler='0 -90 0' material='robot'/>
      <geom type='mesh' mesh='base-2' pos='-0.001 -0.091 0' euler='0 -90 0' material='robot'/>
      <geom type='mesh' mesh='base-3' pos='-0.001 0.12 0.4' euler='-10 -90 0' material='robot'/>
      <geom type='mesh' mesh='base-4' pos='-0.001 -0.12 0.4' euler='10 -90 0' material='robot'/>
      <geom type='box' size='0.0975 0.087 0.245' pos='0.008 0 0.21' euler='-0 0 -0' friction='0.7 0.01 0.005'  mass='15.028392' class='collision'/>
      <geom type='cylinder' size='0.05 0.0325' pos='0.02 0 0.49' euler='-0 0 -0' friction='0.7 0.01 0.005'  mass='15.028392' class='collision'/>
      <site name='imu' pos='0 0 0' euler='0 -90 0' size='0.01'/>  
      <body name='left-hip-roll' pos='-0.001 0.091 0' euler='21.5 -90 0'>
        <inertial pos='-0.001967 0.000244 0.031435' mass='0.915088' fullinertia='0.001017 0.001148 0.000766 -3e-06 1.3e-05 -4e-06' />
        <joint name='left-hip-roll' type='hinge' axis='0 0 1' range='-60 60' stiffness='0' frictionloss='1' damping='1' armature='0.173824' limited='true' pos='0 0 0'/>
        <geom type='mesh' mesh='left-hip-roll-0' pos='0 0 0' euler='-0 0 -0' material='robot'/>
        <body name='left-hip-yaw' pos='-0.0505 0 0.044' euler='0 -90 0'>
          <inertial pos='1e-05 -0.001945 0.042033' mass='0.818753' fullinertia='0.001627 0.001929 0.00077 -1e-06 2e-06 5.3e-05' />
          <joint name='left-hip-yaw' type='hinge' axis='0 0 1' range='-40 40' stiffness='0' frictionloss='1' damping='1' armature='0.0679' limited='true' pos='0 0 0'/>
          <geom type='mesh' mesh='left-hip-yaw-0' pos='0 0 0' euler='-0 0 -0' material='robot'/>
          <body name='left-hip-pitch' pos='0 0.004 0.068' euler='90 0 135'>
            <inertial pos='0.060537 0.000521 -0.038857' mass='6.244279' fullinertia='0.011533 0.033345 0.033958 -0.000171 0.000148 0.000178' />
            <joint name='left-hip-pitch' type='hinge' axis='0 0 -1' range='-60 90' stiffness='0' frictionloss='0.5' damping='1' armature='0.120473' limited='true' pos='0 0 0'/>
            <geom type='mesh' mesh='left-hip-pitch-0' pos='0 0 0' euler='-0 0 -0' material='robot'/>
            <geom type='cylinder' size='0.05 0.072' pos='0 0 -0.04' euler='-0 0 -0' friction='0.7 0.01 0.005' contype='4' conaffinity='3' mass='6.244279' class='collision'/>
            <geom type='cylinder' size='0.05 0.072' pos='0.12 0 -0.04' euler='-0 0 -0' friction='0.7 0.01 0.005' contype='4' conaffinity='3' mass='6.244279' class='collision'/>
            <geom type='box' size='0.06 0.05 0.072' pos='0.06 0 -0.04' euler='-0 0 -0' friction='0.7 0.01 0.005' contype='4' conaffinity='3' mass='6.244279' class='collision'/>
            <body name='left-achilles-rod' pos='0 0 0.046' euler='4.09 0.05 -82.27'>
              <inertial pos='0.2506 0 0' mass='0.178148' fullinertia='3e-06 0.004501 0.004501 0 0 0' />
              <joint name='left-achilles-rod' type='ball' axis='0 0 1'  stiffness='0' frictionloss='0' damping='0.01' armature='0' limited='false' pos='0 0 0'/>
              <geom type='mesh' mesh='left-achilles-rod-0' pos='0 0 0' euler='-0 0 -0' material='robot'/>
              <geom type='capsule' size='0.007 0.25' pos='0.25 0 0' euler='4 90 0' friction='0.7 0.01 0.005' contype='4' conaffinity='3' mass='0.178148' class='collision'/>
            </body>
            <body name='left-knee' pos='0.12 0 0.0045' euler='0 0 -90'>
              <inertial pos='0.045641 0.042154 0.001657' mass='1.227077' fullinertia='0.002643 0.005098 0.007019 -0.001832 6.6e-05 4.5e-05' />
              <joint name='left-knee' type='hinge' axis='0 0 1' range='-80 58.4' stiffness='0' frictionloss='0.5' damping='1' armature='0.120473' limited='true' pos='0 0 0'/>
              <geom type='mesh' mesh='left-knee-0' pos='0 0 0' euler='-0 0 -0' material='robot'/>
              <body name='left-shin' pos='0.060677 0.047406 0' euler='-0 0 -0'>
                <inertial pos='0.174265 0.010265 0.00107' mass='0.895793' fullinertia='0.001128 0.022492 0.022793 0.001098 0.000196 -3e-06' />
                <!-- <joint name='left-shin' type='hinge' axis='0 0 1'  stiffness='6000' frictionloss='0' damping='0' armature='0' limited='false' pos='0 0 0'/> -->
                <geom type='mesh' mesh='left-shin-0' pos='0 0 0' euler='-0 0 -0' material='robot'/>
                <geom type='cylinder' size='0.03 0.1715' pos='0.23 0 0' euler='0 90 0' friction='0.7 0.01 0.005' contype='4' conaffinity='3' mass='0.895793' class='collision'/>
                <geom type='cylinder' size='0.05 0.1' pos='0.125 0.009 0' euler='90 84 -3.042764221e-14' friction='0.7 0.01 0.005' contype='4' conaffinity='3' mass='0.895793' class='collision'/>
                <body name='left-tarsus' pos='0.434759 0.02 0' euler='-0 0 103'>
                  <inertial pos='0.100777 -0.029183 0.000678' mass='1.322865' fullinertia='0.000932 0.016409 0.016501 0.00061 0.000102 9e-06' />
                  <joint name='left-tarsus' type='hinge' axis='0 0 1' range='-50.3 71.6' stiffness='0' frictionloss='0' damping='0' armature='0' limited='true' pos='0 0 0'/>
                  <geom type='mesh' mesh='left-tarsus-0' pos='0 0 0' euler='-0 0 -0' material='robot'/>
                  <geom type='capsule' size='0.02 0.18' pos='0.21 -0.03 0' euler='0 90 0' friction='0.7 0.01 0.005' contype='4' conaffinity='3' mass='1.322865' class='collision'/>
                  <geom type='box' size='0.007 0.07 0.03' pos='-0.07 -0.012 0' euler='5 3.975693352e-16 65' friction='0.7 0.01 0.005' contype='4' conaffinity='3' mass='1.322865' class='collision'/>
                  <body name='left-heel-spring' pos='-0.01766 -0.029456 0.00104' euler='4.47 0.32 155.8'>
                    <inertial pos='0.049086 0.004739 -4.5e-05' mass='0.230018' fullinertia='5.5e-05 0.00074 0.000701 1.5e-05 1e-06 0' />
                    <!-- <joint name='left-heel-spring' type='hinge' axis='0 0 1' range='-6 6' stiffness='4375' frictionloss='0' damping='0' armature='0' limited='true' pos='0 0 0'/> -->
                    <geom type='mesh' mesh='left-heel-spring-0' pos='0 0 0' euler='-0 0 -0' material='robot'/>
                  </body>
                  <body name='left-toe-A' pos='0.059 -0.034 -0.0276' euler='-180 0 88.96'>
                    <inertial pos='0.005161 1e-06 -0.002248' mass='0.139557' fullinertia='2.9e-05 5.8e-05 7.4e-05 0 -4e-06 0' />
                    <joint name='left-toe-A' type='hinge' axis='0 0 1' range='-46.2755 44.9815' stiffness='0' frictionloss='1' damping='1' armature='0.036089' limited='true' pos='0 0 0'/>
                    <geom type='mesh' mesh='left-toe-A-0' pos='0 0 0' euler='-0 0 -0' material='robot'/>
                    <body name='left-toe-A-rod' pos='0.057 0 -0.008' euler='0.34 2.14 -88.45'>
                      <inertial pos='0.171071 0 0' mass='0.090983' fullinertia='1e-06 0.001182 0.001182 0 0 0' />
                      <joint name='left-toe-A-rod' type='ball' axis='0 0 1'  stiffness='0' frictionloss='0' damping='0.01' armature='0' limited='false' pos='0 0 0'/>
                      <geom type='mesh' mesh='left-toe-A-rod-0' pos='0 0 0' euler='-0 0 -0' material='robot'/>
                      <geom type='capsule' size='0.007 0.17' pos='0.17 0 0' euler='4 90 0' friction='0.7 0.01 0.005' contype='4' conaffinity='3' mass='0.090983' class='collision'/>
                    </body>
                  </body>
                  <body name='left-toe-B' pos='0.111 -0.034 0.0276' euler='0 0 -88.96'>
                    <inertial pos='0.005161 1e-06 -0.002248' mass='0.139557' fullinertia='2.9e-05 5.8e-05 7.4e-05 0 -4e-06 0' />
                    <joint name='left-toe-B' type='hinge' axis='0 0 1' range='-45.8918 45.5476' stiffness='0' frictionloss='1' damping='1' armature='0.036089' limited='true' pos='0 0 0'/>
                    <geom type='mesh' mesh='left-toe-B-0' pos='0 0 0' euler='-0 0 -0' material='robot'/>
                    <body name='left-toe-B-rod' pos='0.057 0 -0.008' euler='-0.22 -3.08 88.34'>
                      <inertial pos='0.142991 0 0' mass='0.079507' fullinertia='1e-06 0.000768 0.000768 0 0 0' />
                      <joint name='left-toe-B-rod' type='ball' axis='0 0 1'  stiffness='0' frictionloss='0' damping='0.01' armature='0' limited='false' pos='0 0 0'/>
                      <geom type='mesh' mesh='left-toe-B-rod-0' pos='0 0 0' euler='-0 0 -0' material='robot'/>
                      <geom type='capsule' size='0.007 0.144' pos='0.144 0 0' euler='4 90 0' friction='0.7 0.01 0.005' contype='4' conaffinity='3' mass='0.079507' class='collision'/>
                    </body>
                  </body>
                  <body name='left-toe-pitch' pos='0.408 -0.04 0' euler='-0 0 71.75'>
                    <inertial pos='-0.000141 2e-06 3e-06' mass='0.043881' fullinertia='5e-06 8e-06 4e-06 0 0 0' />
                    <joint name='left-toe-pitch' type='hinge' axis='0 0 1' range='-44 34' stiffness='0' frictionloss='0' damping='0' armature='0' limited='true' pos='0 0 0'/>
                    <geom type='mesh' mesh='left-toe-pitch-0' pos='0 0 0' euler='-0 0 -0' material='robot'/>
                    <body name='left-toe-roll' pos='0 0 0' euler='0 90 0'>
                      <inertial pos='9e-06 -0.028084 -0.023204' mass='0.531283' fullinertia='0.00187 0.001616 0.000843 0 0 0.000566' />
                      <joint name='left-toe-roll' type='hinge' axis='0 0 1' range='-37 33' stiffness='0' frictionloss='0' damping='0' armature='0' limited='true' pos='0 0 0'/>
                      <geom type='mesh' mesh='left-toe-roll-0' pos='0 0 0' euler='-0 0 -0' material='robot'/>
                      <geom type='box' size='0.04 0.1175 0.0115' pos='0 -0.0437 -0.0255' euler='-60 0 0' friction='0.7 0.01 0.005' contype='4' conaffinity='3' mass='0.531283' class='collision'/>
                      <site name='tl' type='box' size='0.04 0.12 0.012' pos='0 -0.0437 -0.0255' euler='-60 0 0' rgba='0 1 0 1' />
                      <body name='left-foot' pos='0 -0.05456 -0.0315' euler='-60 0 -90'>
                      </body>
                    </body>
                  </body>
                </body>
              </body>
            </body>
          </body>
        </body>
      </body>
      <body name='left-shoulder-roll' pos='-0.001 0.12 0.4' euler='-10 -90 0'>
        <inertial pos='-0.000819 -0.003158 0.023405' mass='0.535396' fullinertia='0.000704 0.00075 0.000298 1.4e-05 1.2e-05 3.5e-05' />
        <joint name='left-shoulder-roll' type='hinge' axis='0 0 1' range='-75 75' stiffness='0' frictionloss='2' damping='2' armature='0.173824' limited='true' pos='0 0 0'/>
        <geom type='mesh' mesh='left-shoulder-roll-0' pos='0 0 0' euler='0 0 -16' material='robot'/>
        <body name='left-shoulder-pitch' pos='-0.00317 -0.011055 0.0555' euler='90 -16 -45'>
          <inertial pos='-4.2e-05 -0.061882 -0.073788' mass='1.440357' fullinertia='0.006761 0.002087 0.005778 -6e-06 -3e-06 -0.002046' />
          <joint name='left-shoulder-pitch' type='hinge' axis='0 0 -1' range='-145 145' stiffness='0' frictionloss='2' damping='2' armature='0.173824' limited='true' pos='0 0 0'/>
          <geom type='mesh' mesh='left-shoulder-pitch-0' pos='0 0 0' euler='-0 0 -0' material='robot'/>
          <geom type='cylinder' size='0.038 0.07' pos='0 -0.093 -0.1' euler='90 0 -0' friction='0.7 0.01 0.005'  mass='1.440357' class='collision'/>
          <body name='left-shoulder-yaw' pos='0 -0.165 -0.1' euler='90 0 -0'>
            <inertial pos='-3e-05 0.001937 0.11407' mass='1.065387' fullinertia='0.006967 0.007003 0.000673 -1e-06 -1e-06 -1.5e-05' />
            <joint name='left-shoulder-yaw' type='hinge' axis='0 0 1' range='-100 100' stiffness='0' frictionloss='2' damping='1' armature='0.0679' limited='true' pos='0 0 0'/>
            <geom type='mesh' mesh='left-shoulder-yaw-0' pos='0 0 0' euler='-0 0 -0' material='robot'/>
            <geom type='cylinder' size='0.038 0.0675' pos='0 0 0.092558' euler='-0 0 -0' friction='0.7 0.01 0.005'  mass='1.065387' class='collision'/>
            <geom type='cylinder' size='0.03 0.04' pos='0 0.0035 0.185' euler='90 1.590277341e-15 22.5' friction='0.7 0.01 0.005'  mass='1.065387' class='collision'/>
            <body name='left-elbow' pos='0 -0.0385 0.185' euler='90 1.590277341e-15 22.5'>
              <inertial pos='0.107996 0.000521 -0.017765' mass='0.550582' fullinertia='0.000476 0.009564 0.009437 -2.9e-05 0.001403 9e-06' />
              <joint name='left-elbow' type='hinge' axis='0 0 1' range='-77.5 77.5' stiffness='0' frictionloss='2' damping='1' armature='0.173824' limited='true' pos='0 0 0'/>
              <geom type='mesh' mesh='left-elbow-0' pos='0 0 0' euler='-0 0 -0' material='robot'/>
              <geom type='cylinder' size='0.013 0.1565' pos='0.184 0.01 -0.026' euler='170 78 -180' friction='0.7 0.01 0.005'  mass='0.550582' class='collision'/>
              <geom type='sphere' size='0.015' pos='0.37937 0 -0.061912' euler='-0 0 -0' friction='0.7 0.01 0.005'  mass='0.550582' class='collision'/>
              <body name='left-hand' pos='0.369 0 -0.07912' euler='90 0 -10'>
              </body>
            </body>
          </body>
        </body>
      </body>
      <body name='right-hip-roll' pos='-0.001 -0.091 0' euler='-21.5 -90 0'>
        <inertial pos='-0.001967 -0.000244 0.031435' mass='0.915088' fullinertia='0.001017 0.001148 0.000766 3e-06 1.3e-05 4e-06' />
        <joint name='right-hip-roll' type='hinge' axis='0 0 1' range='-60 60' stiffness='0' frictionloss='1' damping='1' armature='0.173824' limited='true' pos='0 0 0'/>
        <geom type='mesh' mesh='right-hip-roll-0' pos='0 0 0' euler='-0 0 -0' material='robot'/>
        <body name='right-hip-yaw' pos='-0.0505 0 0.044' euler='0 -90 0'>
          <inertial pos='1e-05 0.001945 0.042033' mass='0.818753' fullinertia='0.001627 0.001929 0.00077 1e-06 2e-06 -5.3e-05' />
          <joint name='right-hip-yaw' type='hinge' axis='0 0 1' range='-40 40' stiffness='0' frictionloss='1' damping='1' armature='0.0679' limited='true' pos='0 0 0'/>
          <geom type='mesh' mesh='right-hip-yaw-0' pos='0 0 0' euler='-0 0 -0' material='robot'/>
          <body name='right-hip-pitch' pos='0 -0.004 0.068' euler='-90 0 -135'>
            <inertial pos='0.060537 -0.000521 -0.038857' mass='6.244279' fullinertia='0.011533 0.033345 0.033958 0.000171 0.000148 -0.000178' />
            <joint name='right-hip-pitch' type='hinge' axis='0 0 -1' range='-90 60' stiffness='0' frictionloss='0.5' damping='1' armature='0.120473' limited='true' pos='0 0 0'/>
            <geom type='mesh' mesh='right-hip-pitch-0' pos='0 0 0' euler='-0 0 -0' material='robot'/>
            <geom type='cylinder' size='0.05 0.072' pos='0 0 -0.04' euler='-0 0 -0' friction='0.7 0.01 0.005' contype='2' conaffinity='1' mass='6.244279' class='collision'/>
            <geom type='cylinder' size='0.05 0.072' pos='0.12 0 -0.04' euler='-0 0 -0' friction='0.7 0.01 0.005' contype='2' conaffinity='1' mass='6.244279' class='collision'/>
            <geom type='box' size='0.06 0.05 0.072' pos='0.06 0 -0.04' euler='-0 0 -0' friction='0.7 0.01 0.005' contype='2' conaffinity='1' mass='6.244279' class='collision'/>
            <body name='right-achilles-rod' pos='0 0 0.046' euler='-4.09 0.05 82.27'>
              <inertial pos='0.2506 0 0' mass='0.178148' fullinertia='3e-06 0.004501 0.004501 0 0 0' />
              <joint name='right-achilles-rod' type='ball' axis='0 0 1'  stiffness='0' frictionloss='0' damping='0.01' armature='0' limited='false' pos='0 0 0'/>
              <geom type='mesh' mesh='right-achilles-rod-0' pos='0 0 0' euler='-0 0 -0' material='robot'/>
              <geom type='capsule' size='0.007 0.25' pos='0.25 0 0' euler='-4 90 0' friction='0.7 0.01 0.005' contype='2' conaffinity='1' mass='0.178148' class='collision'/>
            </body>
            <body name='right-knee' pos='0.12 0 0.0045' euler='-0 0 90'>
              <inertial pos='0.045641 -0.042154 0.001657' mass='1.227077' fullinertia='0.002643 0.005098 0.007019 0.001832 6.6e-05 -4.5e-05' />
              <joint name='right-knee' type='hinge' axis='0 0 1' range='-58.4 80' stiffness='0' frictionloss='0.5' damping='1' armature='0.120473' limited='true' pos='0 0 0'/>
              <geom type='mesh' mesh='right-knee-0' pos='0 0 0' euler='-0 0 -0' material='robot'/>
              <body name='right-shin' pos='0.060677 -0.047406 0' euler='-0 0 -0'>
                <inertial pos='0.174265 -0.010265 0.00107' mass='0.895793' fullinertia='0.001128 0.022492 0.022793 -0.001098 0.000196 3e-06' />
                <!-- <joint name='right-shin' type='hinge' axis='0 0 1'  stiffness='6000' frictionloss='0' damping='0' armature='0' limited='false' pos='0 0 0'/> -->
                <geom type='mesh' mesh='right-shin-0' pos='0 0 0' euler='-0 0 -0' material='robot'/>
                <geom type='cylinder' size='0.03 0.1715' pos='0.23 0 0' euler='0 90 0' friction='0.7 0.01 0.005' contype='2' conaffinity='1' mass='0.895793' class='collision'/>
                <geom type='cylinder' size='0.05 0.1' pos='0.125 -0.009 0' euler='-90 84 3.042764221e-14' friction='0.7 0.01 0.005' contype='2' conaffinity='1' mass='0.895793' class='collision'/>
                <body name='right-tarsus' pos='0.434759 -0.02 0' euler='0 0 -103'>
                  <inertial pos='0.100777 0.029183 0.000678' mass='1.322865' fullinertia='0.000932 0.016409 0.016501 -0.00061 0.000102 -9e-06' />
                  <joint name='right-tarsus' type='hinge' axis='0 0 1' range='-71.6 50.3' stiffness='0' frictionloss='0' damping='0' armature='0' limited='true' pos='0 0 0'/>
                  <geom type='mesh' mesh='right-tarsus-0' pos='0 0 0' euler='-0 0 -0' material='robot'/>
                  <geom type='capsule' size='0.02 0.18' pos='0.21 0.03 0' euler='0 90 0' friction='0.7 0.01 0.005' contype='2' conaffinity='1' mass='1.322865' class='collision'/>
                  <geom type='box' size='0.007 0.07 0.03' pos='-0.07 0.012 0' euler='-5 3.975693352e-16 -65' friction='0.7 0.01 0.005' contype='2' conaffinity='1' mass='1.322865' class='collision'/>
                  <body name='right-heel-spring' pos='-0.01766 0.029456 0.00104' euler='-4.47 0.32 -155.8'>
                    <inertial pos='0.049086 -0.004739 -4.5e-05' mass='0.230018' fullinertia='5.5e-05 0.00074 0.000701 -1.5e-05 1e-06 0' />
                    <!-- <joint name='right-heel-spring' type='hinge' axis='0 0 1' range='-6 6' stiffness='4375' frictionloss='0' damping='0' armature='0' limited='true' pos='0 0 0'/> -->
                    <geom type='mesh' mesh='right-heel-spring-0' pos='0 0 0' euler='-0 0 -0' material='robot'/>
                  </body>
                  <body name='right-toe-A' pos='0.059 0.034 -0.0276' euler='180 0 -88.96'>
                    <inertial pos='0.005161 -1e-06 -0.002248' mass='0.139557' fullinertia='2.9e-05 5.8e-05 7.4e-05 0 -4e-06 0' />
                    <joint name='right-toe-A' type='hinge' axis='0 0 1' range='-44.9815 46.2755' stiffness='0' frictionloss='1' damping='1' armature='0.036089' limited='true' pos='0 0 0'/>
                    <geom type='mesh' mesh='right-toe-A-0' pos='0 0 0' euler='-0 0 -0' material='robot'/>
                    <body name='right-toe-A-rod' pos='0.057 0 -0.008' euler='-0.34 2.14 88.45'>
                      <inertial pos='0.171071 0 0' mass='0.090983' fullinertia='1e-06 0.001182 0.001182 0 0 0' />
                      <joint name='right-toe-A-rod' type='ball' axis='0 0 1'  stiffness='0' frictionloss='0' damping='0.01' armature='0' limited='false' pos='0 0 0'/>
                      <geom type='mesh' mesh='right-toe-A-rod-0' pos='0 0 0' euler='-0 0 -0' material='robot'/>
                      <geom type='capsule' size='0.007 0.17' pos='0.17 0 0' euler='-4 90 0' friction='0.7 0.01 0.005' contype='2' conaffinity='1' mass='0.090983' class='collision'/>
                    </body>
                  </body>
                  <body name='right-toe-B' pos='0.111 0.034 0.0276' euler='-0 0 88.96'>
                    <inertial pos='0.005161 -1e-06 -0.002248' mass='0.139557' fullinertia='2.9e-05 5.8e-05 7.4e-05 0 -4e-06 0' />
                    <joint name='right-toe-B' type='hinge' axis='0 0 1' range='-45.5476 45.8918' stiffness='0' frictionloss='1' damping='1' armature='0.036089' limited='true' pos='0 0 0'/>
                    <geom type='mesh' mesh='right-toe-B-0' pos='0 0 0' euler='-0 0 -0' material='robot'/>
                    <body name='right-toe-B-rod' pos='0.057 0 -0.008' euler='0.22 -3.08 -88.34'>
                      <inertial pos='0.142991 0 0' mass='0.079507' fullinertia='1e-06 0.000768 0.000768 0 0 0' />
                      <joint name='right-toe-B-rod' type='ball' axis='0 0 1'  stiffness='0' frictionloss='0' damping='0.01' armature='0' limited='false' pos='0 0 0'/>
                      <geom type='mesh' mesh='right-toe-B-rod-0' pos='0 0 0' euler='-0 0 -0' material='robot'/>
                      <geom type='capsule' size='0.007 0.144' pos='0.144 0 0' euler='-4 90 0' friction='0.7 0.01 0.005' contype='2' conaffinity='1' mass='0.079507' class='collision'/>
                    </body>
                  </body>
                  <body name='right-toe-pitch' pos='0.408 0.04 0' euler='0 0 -71.75'>
                    <inertial pos='-0.000141 -2e-06 3e-06' mass='0.043881' fullinertia='5e-06 8e-06 4e-06 0 0 0' />
                    <joint name='right-toe-pitch' type='hinge' axis='0 0 1' range='-34 44' stiffness='0' frictionloss='0' damping='0' armature='0' limited='true' pos='0 0 0'/>
                    <geom type='mesh' mesh='right-toe-pitch-0' pos='0 0 0' euler='-0 0 -0' material='robot'/>
                    <body name='right-toe-roll' pos='0 0 0' euler='0 90 0'>
                      <inertial pos='9e-06 0.028084 -0.023204' mass='0.531283' fullinertia='0.00187 0.001616 0.000843 0 0 -0.000566' />
                      <joint name='right-toe-roll' type='hinge' axis='0 0 1' range='-33 37' stiffness='0' frictionloss='0' damping='0' armature='0' limited='true' pos='0 0 0'/>
                      <geom type='mesh' mesh='right-toe-roll-0' pos='0 0 0' euler='-0 0 -0' material='robot'/>
                      <geom type='box' size='0.04 0.1175 0.0115' pos='0 0.0437 -0.0255' euler='60 0 -0' friction='0.7 0.01 0.005' contype='2' conaffinity='1' mass='0.531283' class='collision'/>
                      <site name='tr' type='box' size='0.04 0.12 0.012' pos='0 0.0437 -0.0255' euler='60 0 0' rgba='0 1 0 1' />
                      <body name='right-foot' pos='0 0.05456 -0.0315' euler='60 0 90'>
                      </body>
                    </body>
                  </body>
                </body>
              </body>
            </body>
          </body>
        </body>
      </body>
      <body name='right-shoulder-roll' pos='-0.001 -0.12 0.4' euler='10 -90 0'>
        <inertial pos='-0.000819 0.003158 0.023405' mass='0.535396' fullinertia='0.000704 0.00075 0.000298 -1.4e-05 1.2e-05 -3.5e-05' />
        <joint name='right-shoulder-roll' type='hinge' axis='0 0 1' range='-75 75' stiffness='0' frictionloss='2' damping='2' armature='0.173824' limited='true' pos='0 0 0'/>
        <geom type='mesh' mesh='right-shoulder-roll-0' pos='0 0 0' euler='-0 0 16' material='robot'/>
        <body name='right-shoulder-pitch' pos='-0.00317 0.011055 0.0555' euler='-90 -16 45'>
          <inertial pos='-4.2e-05 0.061882 -0.073788' mass='1.440357' fullinertia='0.006761 0.002087 0.005778 6e-06 -3e-06 0.002046' />
          <joint name='right-shoulder-pitch' type='hinge' axis='0 0 -1' range='-145 145' stiffness='0' frictionloss='2' damping='2' armature='0.173824' limited='true' pos='0 0 0'/>
          <geom type='mesh' mesh='right-shoulder-pitch-0' pos='0 0 0' euler='-0 0 -0' material='robot'/>
          <geom type='cylinder' size='0.038 0.07' pos='0 0.093 -0.1' euler='-90 0 0' friction='0.7 0.01 0.005'  mass='1.440357' class='collision'/>
          <body name='right-shoulder-yaw' pos='0 0.165 -0.1' euler='-90 0 0'>
            <inertial pos='-3e-05 -0.001937 0.11407' mass='1.065387' fullinertia='0.006967 0.007003 0.000673 1e-06 -1e-06 1.5e-05' />
            <joint name='right-shoulder-yaw' type='hinge' axis='0 0 1' range='-100 100' stiffness='0' frictionloss='2' damping='1' armature='0.0679' limited='true' pos='0 0 0'/>
            <geom type='mesh' mesh='right-shoulder-yaw-0' pos='0 0 0' euler='-0 0 -0' material='robot'/>
            <geom type='cylinder' size='0.038 0.0675' pos='0 0 0.092558' euler='-0 0 -0' friction='0.7 0.01 0.005'  mass='1.065387' class='collision'/>
            <geom type='cylinder' size='0.03 0.04' pos='0 -0.0035 0.185' euler='-90 1.590277341e-15 -22.5' friction='0.7 0.01 0.005'  mass='1.065387' class='collision'/>
            <body name='right-elbow' pos='0 0.0385 0.185' euler='-90 1.590277341e-15 -22.5'>
              <inertial pos='0.107996 -0.000521 -0.017765' mass='0.550582' fullinertia='0.000476 0.009564 0.009437 2.9e-05 0.001403 -9e-06' />
              <joint name='right-elbow' type='hinge' axis='0 0 1' range='-77.5 77.5' stiffness='0' frictionloss='2' damping='1' armature='0.173824' limited='true' pos='0 0 0'/>
              <geom type='mesh' mesh='right-elbow-0' pos='0 0 0' euler='-0 0 -0' material='robot'/>
              <geom type='cylinder' size='0.013 0.1565' pos='0.184 -0.01 -0.026' euler='-170 78 180' friction='0.7 0.01 0.005'  mass='0.550582' class='collision'/>
              <geom type='sphere' size='0.015' pos='0.37937 0 -0.061912' euler='-0 0 -0' friction='0.7 0.01 0.005'  mass='0.550582' class='collision'/>
              <body name='right-hand' pos='0.369 0 -0.07912' euler='-90 0 10'>
              </body>
            </body>
          </body>
        </body>
      </body>
    </body>
    
    <body>
      <geom type='cylinder' size='0.5 1.0' rgba="0.58 0.65 0.65 1" pos='1.0 1.0 0.5' euler='0 0 0' friction='0.7 0.01 0.005'  mass='10' class='collision'/>
      <geom type='cylinder' size='0.5 0.4' rgba="0.93 0.905 0.882 1" pos='2.0 2.0 0.5' euler='0 0 0' friction='0.7 0.01 0.005'  mass='10' class='collision'/>
      <geom type='cylinder' size='0.8 0.6' rgba="0.93 0.905 0.882 1" pos='6.0 4.0 0.5' euler='0 0 0' friction='0.7 0.01 0.005'  mass='10' class='collision'/>
      <geom type='cylinder' size='1.0 1.0' rgba="0.42 0.48 0.54 1" pos='6.4 7.4 0.5' euler='0 0 0' friction='0.7 0.01 0.005'  mass='10' class='collision'/>
      <geom type='cylinder' size='0.4 0.6' rgba="0.93 0.905 0.882 1" pos='4.8 0.8 0.5' euler='0 0 0' friction='0.7 0.01 0.005'  mass='10' class='collision'/>
      <geom type='cylinder' size='0.3 0.5' rgba="0.93 0.905 0.882 1" pos='2.0 6.0 0.5' euler='0 0 0' friction='0.7 0.01 0.005'  mass='10' class='collision'/>
      <!-- <geom type='cylinder' size='0.1 0.01' rgba="0.0 0.0 1.0 1" pos='0.0 0.0 0.0' euler='0 0 0' friction='0.7 0.01 0.005'  mass='10' class='collision'/>
      <geom type='box' size='0.1 0.1 0.01' rgba="1.0 0.0 0.0 1" pos='10.0 10.0 0.0' euler='0 0 0' friction='0.7 0.01 0.005'  mass='10' class='collision'/> -->

      <geom type='cylinder' size='0.1 0.01' rgba="0.0 0.0 1.0 1" pos='0.0 0.0 0.0' euler='0 0 0' friction='0.7 0.01 0.005'  mass='10' />
      <geom type='box' size='0.1 0.1 0.01' rgba="1.0 0.0 0.0 1" pos='10.0 10.0 0.0' euler='0 0 0' friction='0.7 0.01 0.005'  mass='10' />
      
      <!-- <geom type='cylinder' size='0.42 0.6' rgba="0.93 0.905 0.882 1" pos='3.67 3.12 0.5' euler='0 0 0' friction='0.7 0.01 0.005'  mass='10' class='collision'/>
      <geom type='cylinder' size='0.5 0.6' rgba="0.93 0.905 0.882 1" pos='4.88 0.05 0.5' euler='0 0 0' friction='0.7 0.01 0.005'  mass='10' class='collision'/>
      <geom type='cylinder' size='0.95 1.0' rgba="0.42 0.48 0.54 1" pos='0.52 6.12 0.5' euler='0 0 0' friction='0.7 0.01 0.005'  mass='10' class='collision'/>
      <geom type='cylinder' size='0.29 1.4' rgba="0.42 0.48 0.54 1" pos='1.16 2.32 0.0' euler='0 0 0' friction='0.7 0.01 0.005'  mass='10' class='collision'/>
      <geom type='ellipsoid' size='0.41 0.32 0.8' rgba="0.63 0.32 0.18 1" pos='3.64 8.43 0.0' euler='0 0 142.09' friction='0.7 0.01 0.005'  mass='10' class='collision'/>
      <geom type='ellipsoid' size='0.78 0.42 0.6' rgba="0.63 0.32 0.18 1" pos='8.31 8.39 0.0' euler='0 0 162.14' friction='0.7 0.01 0.005'  mass='10' class='collision'/>
      <geom type='ellipsoid' size='0.88 0.74 0.9' rgba="0.58 0.65 0.65 1" pos='7.31 3.85 0.0' euler='0 0 10.88' friction='0.7 0.01 0.005'  mass='10' class='collision'/>
      <geom type='ellipsoid' size='0.41 0.23 0.9' rgba="0.58 0.65 0.65 1" pos='9.41 4.95 0.0' euler='0 0 134.07' friction='0.7 0.01 0.005'  mass='10' class='collision'/> -->
      <!-- <geom type='cylinder' size=' 0.83 0.6' rgba="0.93 0.905 0.882 1" pos='1.83 4.14 0.5' euler='0 0 0' friction='0.7 0.01 0.005'  mass='10' class='collision'/> 
      <geom type='cylinder' size=' 0.94 0.6' rgba="0.93 0.905 0.882 1" pos='2.9 1.23 0.5' euler='0 0 0' friction='0.7 0.01 0.005'  mass='10' class='collision'/> 
      <geom type='cylinder' size=' 0.87 0.6' rgba="0.42 0.48 0.54 1" pos='4.43 8.02 0.5' euler='0 0 0' friction='0.7 0.01 0.005'  mass='10' class='collision'/> 
      <geom type='cylinder' size=' 0.51 0.6' rgba="0.42 0.48 0.54 1" pos='6.12 6.53 0.5' euler='0 0 0' friction='0.7 0.01 0.005'  mass='10' class='collision'/> 
      <geom type='ellipsoid' size='0.85 0.65 0.8' rgba="0.63 0.32 0.18 1" pos='4.88 4.48 0.0' euler='0 0 10.886198107485642' friction='0.7 0.01 0.005'  mass='10' class='collision'/>
      <geom type='ellipsoid' size='0.25 0.22 0.8' rgba="0.63 0.32 0.18 1" pos='0.32 2.58 0.0' euler='0 0 156.99043586584557' friction='0.7 0.01 0.005'  mass='10' class='collision'/>
      <geom type='ellipsoid' size='0.96 0.52 0.8' rgba="0.58 0.65 0.65 1" pos='8.7 3.47 0.0' euler='0 0 26.92901637114869' friction='0.7 0.01 0.005'  mass='10' class='collision'/>
      <geom type='ellipsoid' size='0.52 0.29 0.8' rgba="0.58 0.65 0.65 1" pos='8.37 9.47 0.0' euler='0 0 177.04395869542435' friction='0.7 0.01 0.005'  mass='10' class='collision'/> -->

      <!-- <geom type='box' size='5 0.1 5' rgba="10.0 10.0 10.0 1" pos='0.0 0.5 0.0' euler='0 0 0' friction='0.7 0.01 0.005'  mass='10' class='collision'/> -->

      <!-- <geom type='cylinder' size='0.1 0.01' rgba="0.0 0.0 1.0 1" pos='0.0 0.0 0.0' euler='0 0 0' friction='0.7 0.01 0.005'  mass='10' />
      <geom type='box' size='0.1 0.1 0.01' rgba="1.0 0.0 0.0 1" pos='10.0 10.0 0.0' euler='0 0 0' friction='0.7 0.01 0.005'  mass='10' /> -->
      <!-- <geom type='cylinder' size='0.8 0.6' rgba="0.93 0.905 0.882 1" pos='6.0 4.0 0.5' euler='0 0 0' friction='0.7 0.01 0.005'  mass='10' class='collision'/>
      <geom type='cylinder' size='1.0 1.0' rgba="0.42 0.48 0.54 1" pos='6.4 7.4 0.5' euler='0 0 0' friction='0.7 0.01 0.005'  mass='10' class='collision'/>
      <geom type='cylinder' size='0.3 1.4' rgba="0.42 0.48 0.54 1" pos='8.0 2.0 0.0' euler='0 0 0' friction='0.7 0.01 0.005'  mass='10' class='collision'/>
      <geom type='ellipsoid' size='0.4 0.32 0.8' rgba="0.58 0.65 0.65 1" pos='4.8 0.8 0.0' euler='0 0 15' friction='0.7 0.01 0.005'  mass='10' class='collision'/>
      <geom type='ellipsoid' size='1.1 0.7 0.6' rgba="0.58 0.65 0.65 1" pos='1.5 1.5 0.0' euler='0 0 45' friction='0.7 0.01 0.005'  mass='10' class='collision'/>
      <geom type='ellipsoid' size='0.6 1.2 0.9' rgba="0.58 0.65 0.65 1" pos='3.0 5.0 0.0' euler='0 0 60' friction='0.7 0.01 0.005'  mass='10' class='collision'/> -->


      <!-- <geom type='cylinder' size='0.1 0.01' rgba="0.0 0.0 1.0 1" pos='0.0 0.0 0.0' euler='0 0 0' friction='0.7 0.01 0.005'  mass='10' />
      <geom type='box' size='0.1 0.1 0.01' rgba="1.0 0.0 0.0 1" pos='10.0 10.0 0.0' euler='0 0 0' friction='0.7 0.01 0.005'  mass='10' />
      <geom type='cylinder' size='0.8 0.6' rgba="0.93 0.905 0.882 1" pos='6.0 4.0 0.5' euler='0 0 0' friction='0.7 0.01 0.005'  mass='10' />
      <geom type='cylinder' size='1.0 1.0' rgba="0.42 0.48 0.54 1" pos='6.4 7.4 0.5' euler='0 0 0' friction='0.7 0.01 0.005'  mass='10' />
      <geom type='cylinder' size='0.3 1.4' rgba="0.42 0.48 0.54 1" pos='8.0 2.0 0.0' euler='0 0 0' friction='0.7 0.01 0.005'  mass='10' />
      <geom type='ellipsoid' size='0.4 0.32 0.8' rgba="0.58 0.65 0.65 1" pos='4.8 0.8 0.0' euler='0 0 15' friction='0.7 0.01 0.005'  mass='10' />
      <geom type='ellipsoid' size='1.1 0.7 0.6' rgba="0.58 0.65 0.65 1" pos='1.5 1.5 0.0' euler='0 0 45' friction='0.7 0.01 0.005'  mass='10' />
      <geom type='ellipsoid' size='0.6 1.2 0.9' rgba="0.58 0.65 0.65 1" pos='3.0 5.0 0.0' euler='0 0 60' friction='0.7 0.01 0.005'  mass='10' /> -->
    </body>
    
    <!-- visialization -->
    <site name="current_foothold"   type="box" size="0.15 0.1 0.005" pos="0.16 0.2 0"  euler="0 0 0" rgba="0 0 0 1"/>
    <site name="next_foothold"      type="box" size="0.15 0.1 0.005" pos="0.16 0.2 0"  euler="0 0 0" rgba="0 1 0 1"/>
  
  </worldbody>
  <equality>
    <connect name='left-achilles-rod' body1='left-heel-spring' body2='left-achilles-rod' anchor='0.113789 -0.011056 0' />
    <connect name='left-toe-A-rod' body1='left-toe-roll' body2='left-toe-A-rod' anchor='0.0179 -0.009551 -0.054164' />
    <connect name='left-toe-B-rod' body1='left-toe-roll' body2='left-toe-B-rod' anchor='-0.0181 -0.009551 -0.054164' />
    <connect name='right-achilles-rod' body1='right-heel-spring' body2='right-achilles-rod' anchor='0.113789 0.011056 0' />
    <connect name='right-toe-A-rod' body1='right-toe-roll' body2='right-toe-A-rod' anchor='0.0179 0.009551 -0.054164' />
    <connect name='right-toe-B-rod' body1='right-toe-roll' body2='right-toe-B-rod' anchor='-0.0181 0.009551 -0.054164' />
  </equality>
        <actuator>
              <motor name='left_hip_roll_motor'        joint='left-hip-roll'        gear='80' ctrllimited='true' ctrlrange='-1.583530725 1.583530725'/>
              <motor name='left_hip_yaw_motor'         joint='left-hip-yaw'         gear='50' ctrllimited='true' ctrlrange='-1.58353072 1.58353072'/>
              <motor name='left_hip_pitch_motor'       joint='left-hip-pitch'       gear='16' ctrllimited='true' ctrlrange='-13.557993625 13.557993625'/>
              <motor name='left_knee_motor'            joint='left-knee'            gear='16' ctrllimited='true' ctrlrange='-14.457309375 14.457309375'/>
              <!-- <motor name="left_tarsus_motor"          joint="left-tarsus"          gear="1"  ctrllimited='true' ctrlrange='-0.000001 0.000001'/> -->
              <motor name='left_toe_A_motor'           joint='left-toe-A'           gear='50' ctrllimited='true' ctrlrange='-0.8395188400000001 0.8395188400000001'/>
              <motor name='left_toe_B_motor'           joint='left-toe-B'           gear='50' ctrllimited='true' ctrlrange='-0.8395188400000001 0.8395188400000001'/>
              <!-- <motor name="toe_pitch_joint_left"       joint="left-toe-pitch"       gear="1"  ctrllimited='true' ctrlrange='-0.000001 0.000001'/> -->
              <!-- <motor name="toe_roll_joint_left"        joint="left-toe-roll"        gear="1"  ctrllimited='true' ctrlrange='-0.000001 0.000001'/> -->
              <motor name='left_shoulder_roll_motor'   joint='left-shoulder-roll'   gear='80' ctrllimited='true' ctrlrange='-1.583530725 1.583530725'/>
              <motor name='left_shoulder_pitch_motor'  joint='left-shoulder-pitch'  gear='80' ctrllimited='true' ctrlrange='-1.583530725 1.583530725'/>
              <motor name='left_shoulder_yaw_motor'    joint='left-shoulder-yaw'    gear='50' ctrllimited='true' ctrlrange='-1.58353072 1.58353072'/>
              <motor name='left_elbow_motor'           joint='left-elbow'           gear='80' ctrllimited='true' ctrlrange='-1.583530725 1.583530725'/>
              <motor name='right_hip_roll_motor'       joint='right-hip-roll'       gear='80' ctrllimited='true' ctrlrange='-1.583530725 1.583530725'/>
              <motor name='right_hip_yaw_motor'        joint='right-hip-yaw'        gear='50' ctrllimited='true' ctrlrange='-1.58353072 1.58353072'/>
              <motor name='right_hip_pitch_motor'      joint='right-hip-pitch'      gear='16' ctrllimited='true' ctrlrange='-13.557993625 13.557993625'/>
              <motor name='right_knee_motor'           joint='right-knee'           gear='16' ctrllimited='true' ctrlrange='-14.457309375 14.457309375'/>
              <!-- <motor name="right_tarsus_motor"         joint="right-tarsus"         gear="1"  ctrllimited='true' ctrlrange='-0.000001 0.000001'/> -->
              <motor name='right_toe_A_motor'          joint='right-toe-A'          gear='50' ctrllimited='true' ctrlrange='-0.8395188400000001 0.8395188400000001'/>
              <motor name='right_toe_B_motor'          joint='right-toe-B'          gear='50' ctrllimited='true' ctrlrange='-0.8395188400000001 0.8395188400000001'/>
              <!-- <motor name="toe_pitch_joint_right"      joint="right-toe-pitch"      gear="1"  ctrllimited='true' ctrlrange='-0.000001 0.000001'/> -->
              <!-- <motor name="toe_roll_joint_right"       joint="right-toe-roll"       gear="1"  ctrllimited='true' ctrlrange='-0.000001 0.000001'/> -->
              <motor name='right_shoulder_roll_motor'  joint='right-shoulder-roll'  gear='80' ctrllimited='true' ctrlrange='-1.583530725 1.583530725'/>
              <motor name='right_shoulder_pitch_motor' joint='right-shoulder-pitch' gear='80' ctrllimited='true' ctrlrange='-1.583530725 1.583530725'/>/>
              <motor name='right_shoulder_yaw_motor'   joint='right-shoulder-yaw'   gear='50' ctrllimited='true' ctrlrange='-1.58353072 1.58353072'/>
              <motor name='right_elbow_motor'          joint='right-elbow'          gear='80' ctrllimited='true' ctrlrange='-1.583530725 1.583530725'/>
        </actuator>
  <!-- <sensor>
    <touch name='ts_l' site='tl' />    
    <touch name='ts_r' site='tr' />    
  </sensor> -->
       <sensor>
              <framepos name='base-pos' objtype='xbody' objname='base'/>
              <framequat name='base-quat' objtype='xbody' objname='base'/>
              <framelinacc name='imu_acc' objtype='site' objname='imu'/>

              <jointpos    name='left-hip-roll'            joint='left-hip-roll'/>
              <jointpos    name='left-hip-yaw'             joint='left-hip-yaw'/>
              <jointpos    name='left-hip-pitch'           joint='left-hip-pitch'/>
              <jointpos    name='left-knee'                joint='left-knee'/>
              <jointpos    name='left-tarsus'              joint='left-tarsus'/>
              <jointpos    name='left-toe-A'               joint='left-toe-A'/>
              <jointpos    name='left-toe-B'               joint='left-toe-B'/>
              <jointpos    name='left-toe-pitch'           joint='left-toe-pitch'/>
              <jointpos    name='left-toe-roll'            joint='left-toe-roll'/>
              <jointpos    name='left-shoulder-roll'       joint='left-shoulder-roll'/>
              <jointpos    name='left-shoulder-pitch'      joint='left-shoulder-pitch'/>
              <jointpos    name='left-shoulder-yaw'        joint='left-shoulder-yaw'/>
              <jointpos    name='left-elbow'               joint='left-elbow'/>
              <jointpos    name='right-hip-roll'           joint='right-hip-roll'/>
              <jointpos    name='right-hip-yaw'            joint='right-hip-yaw'/>
              <jointpos    name='right-hip-pitch'          joint='right-hip-pitch'/>
              <jointpos    name='right-knee'               joint='right-knee'/>
              <jointpos    name='right-tarsus'             joint='right-tarsus'/>
              <jointpos    name='right-toe-A'              joint='right-toe-A'/>
              <jointpos    name='right-toe-B'              joint='right-toe-B'/>
              <jointpos    name='right-toe-pitch'          joint='right-toe-pitch'/>
              <jointpos    name='right-toe-roll'           joint='right-toe-roll'/>
              <jointpos    name='right-shoulder-roll'      joint='right-shoulder-roll'/>
              <jointpos    name='right-shoulder-pitch'     joint='right-shoulder-pitch'/>
              <jointpos    name='right-shoulder-yaw'       joint='right-shoulder-yaw'/>
              <jointpos    name='right-elbow'              joint='right-elbow'/>

              <framelinvel name='base-linvel' objtype='xbody' objname='base'/>
              <frameangvel name='base-angvel' objtype='xbody' objname='base'/>

              <jointvel    name='left-hip-roll-vel'        joint='left-hip-roll'/>
              <jointvel    name='left-hip-yaw-vel'         joint='left-hip-yaw'/>
              <jointvel    name='left-hip-pitch-vel'       joint='left-hip-pitch'/>
              <jointvel    name='left-knee-vel'            joint='left-knee'/>
              <jointvel    name='left-tarsus-vel'          joint='left-tarsus'/>
              <jointvel    name='left-toe-A-vel'           joint='left-toe-A'/>
              <jointvel    name='left-toe-B-vel'           joint='left-toe-B'/>
              <jointvel    name='left-toe-pitch-vel'       joint='left-toe-pitch'/>
              <jointvel    name='left-toe-roll-vel'        joint='left-toe-roll'/>
              <jointvel    name='left-shoulder-roll-vel'   joint='left-shoulder-roll'/>
              <jointvel    name='left-shoulder-pitch-vel'  joint='left-shoulder-pitch'/>
              <jointvel    name='left-shoulder-yaw-vel'    joint='left-shoulder-yaw'/>
              <jointvel    name='left-elbow-vel'           joint='left-elbow'/>
              <jointvel    name='right-hip-roll-vel'       joint='right-hip-roll'/>
              <jointvel    name='right-hip-yaw-vel'        joint='right-hip-yaw'/>
              <jointvel    name='right-hip-pitch-vel'      joint='right-hip-pitch'/>
              <jointvel    name='right-knee-vel'           joint='right-knee'/>
              <jointvel    name='right-tarsus-vel'         joint='right-tarsus'/>
              <jointvel    name='right-toe-A-vel'          joint='right-toe-A'/>
              <jointvel    name='right-toe-B-vel'          joint='right-toe-B'/>
              <jointvel    name='right-toe-pitch-vel'      joint='right-toe-pitch'/>
              <jointvel    name='right-toe-roll-vel'       joint='right-toe-roll'/>
              <jointvel    name='right-shoulder-roll-vel'  joint='right-shoulder-roll'/>
              <jointvel    name='right-shoulder-pitch-vel' joint='right-shoulder-pitch'/>
              <jointvel    name='right-shoulder-yaw-vel'   joint='right-shoulder-yaw'/>
              <jointvel    name='right-elbow-vel'          joint='right-elbow'/>

              <touch name='ts_l' site='tl'/>
              <touch name='ts_r' site='tr'/>
       </sensor>  
</mujoco>
